
FAIL Keygenerator ConstraintError when using same id as already generated assert_unreached: unexpected db.error (ConstraintError) Reached unreachable code

